{
 "cells": [
  {
   "cell_type": "code",
   "execution_count": 1,
   "id": "4df45b91",
   "metadata": {},
   "outputs": [],
   "source": [
    "import tensorflow"
   ]
  },
  {
   "cell_type": "code",
   "execution_count": 2,
   "id": "c10d4b89",
   "metadata": {},
   "outputs": [
    {
     "name": "stdout",
     "output_type": "stream",
     "text": [
      "1.15.0\n"
     ]
    }
   ],
   "source": [
    "print(tensorflow.__version__)"
   ]
  },
  {
   "cell_type": "code",
   "execution_count": null,
   "id": "c4e78361",
   "metadata": {},
   "outputs": [
    {
     "name": "stderr",
     "output_type": "stream",
     "text": [
      "ERROR:root:Internal Python error in the inspect module.\n",
      "Below is the traceback from this internal error.\n",
      "\n",
      "ERROR:root:Internal Python error in the inspect module.\n",
      "Below is the traceback from this internal error.\n",
      "\n",
      "ERROR:root:Internal Python error in the inspect module.\n",
      "Below is the traceback from this internal error.\n",
      "\n"
     ]
    },
    {
     "name": "stdout",
     "output_type": "stream",
     "text": [
      "Traceback (most recent call last):\n",
      "  File \"C:\\Users\\atrij\\anaconda3\\envs\\tfdg\\lib\\site-packages\\IPython\\core\\interactiveshell.py\", line 3343, in run_code\n",
      "    exec(code_obj, self.user_global_ns, self.user_ns)\n",
      "  File \"<ipython-input-4-8fd7a15cc125>\", line 1, in <module>\n",
      "    import cv2\n",
      "ModuleNotFoundError: No module named 'cv2'\n",
      "\n",
      "During handling of the above exception, another exception occurred:\n",
      "\n",
      "Traceback (most recent call last):\n",
      "  File \"C:\\Users\\atrij\\anaconda3\\envs\\tfdg\\lib\\site-packages\\IPython\\core\\interactiveshell.py\", line 2044, in showtraceback\n",
      "    stb = value._render_traceback_()\n",
      "AttributeError: 'ModuleNotFoundError' object has no attribute '_render_traceback_'\n",
      "\n",
      "During handling of the above exception, another exception occurred:\n",
      "\n",
      "Traceback (most recent call last):\n",
      "  File \"C:\\Users\\atrij\\anaconda3\\envs\\tfdg\\lib\\site-packages\\IPython\\core\\ultratb.py\", line 1169, in get_records\n",
      "    return _fixed_getinnerframes(etb, number_of_lines_of_context, tb_offset)\n",
      "  File \"C:\\Users\\atrij\\anaconda3\\envs\\tfdg\\lib\\site-packages\\IPython\\core\\ultratb.py\", line 316, in wrapped\n",
      "    return f(*args, **kwargs)\n",
      "  File \"C:\\Users\\atrij\\anaconda3\\envs\\tfdg\\lib\\site-packages\\IPython\\core\\ultratb.py\", line 350, in _fixed_getinnerframes\n",
      "    records = fix_frame_records_filenames(inspect.getinnerframes(etb, context))\n",
      "  File \"C:\\Users\\atrij\\anaconda3\\envs\\tfdg\\lib\\inspect.py\", line 1490, in getinnerframes\n",
      "    frameinfo = (tb.tb_frame,) + getframeinfo(tb, context)\n",
      "  File \"C:\\Users\\atrij\\anaconda3\\envs\\tfdg\\lib\\inspect.py\", line 1448, in getframeinfo\n",
      "    filename = getsourcefile(frame) or getfile(frame)\n",
      "  File \"C:\\Users\\atrij\\anaconda3\\envs\\tfdg\\lib\\inspect.py\", line 696, in getsourcefile\n",
      "    if getattr(getmodule(object, filename), '__loader__', None) is not None:\n",
      "  File \"C:\\Users\\atrij\\anaconda3\\envs\\tfdg\\lib\\inspect.py\", line 733, in getmodule\n",
      "    if ismodule(module) and hasattr(module, '__file__'):\n",
      "  File \"C:\\Users\\atrij\\anaconda3\\envs\\tfdg\\lib\\site-packages\\tensorflow\\__init__.py\", line 50, in __getattr__\n",
      "    module = self._load()\n",
      "  File \"C:\\Users\\atrij\\anaconda3\\envs\\tfdg\\lib\\site-packages\\tensorflow\\__init__.py\", line 44, in _load\n",
      "    module = _importlib.import_module(self.__name__)\n",
      "  File \"C:\\Users\\atrij\\anaconda3\\envs\\tfdg\\lib\\importlib\\__init__.py\", line 126, in import_module\n",
      "    return _bootstrap._gcd_import(name[level:], package, level)\n",
      "  File \"<frozen importlib._bootstrap>\", line 994, in _gcd_import\n",
      "  File \"<frozen importlib._bootstrap>\", line 971, in _find_and_load\n",
      "  File \"<frozen importlib._bootstrap>\", line 955, in _find_and_load_unlocked\n",
      "  File \"<frozen importlib._bootstrap>\", line 665, in _load_unlocked\n",
      "  File \"<frozen importlib._bootstrap_external>\", line 678, in exec_module\n",
      "  File \"<frozen importlib._bootstrap>\", line 219, in _call_with_frames_removed\n",
      "  File \"C:\\Users\\atrij\\anaconda3\\envs\\tfdg\\lib\\site-packages\\tensorflow_core\\contrib\\__init__.py\", line 39, in <module>\n",
      "    from tensorflow.contrib import compiler\n",
      "  File \"C:\\Users\\atrij\\anaconda3\\envs\\tfdg\\lib\\site-packages\\tensorflow_core\\contrib\\compiler\\__init__.py\", line 21, in <module>\n",
      "    from tensorflow.contrib.compiler import jit\n",
      "  File \"C:\\Users\\atrij\\anaconda3\\envs\\tfdg\\lib\\site-packages\\tensorflow_core\\contrib\\compiler\\__init__.py\", line 22, in <module>\n",
      "    from tensorflow.contrib.compiler import xla\n",
      "  File \"C:\\Users\\atrij\\anaconda3\\envs\\tfdg\\lib\\site-packages\\tensorflow_core\\contrib\\compiler\\xla.py\", line 22, in <module>\n",
      "    from tensorflow.python.estimator import model_fn as model_fn_lib\n",
      "  File \"C:\\Users\\atrij\\anaconda3\\envs\\tfdg\\lib\\site-packages\\tensorflow_core\\python\\estimator\\model_fn.py\", line 26, in <module>\n",
      "    from tensorflow_estimator.python.estimator import model_fn\n",
      "  File \"C:\\Users\\atrij\\anaconda3\\envs\\tfdg\\lib\\site-packages\\tensorflow_estimator\\__init__.py\", line 10, in <module>\n",
      "    from tensorflow_estimator._api.v1 import estimator\n",
      "  File \"C:\\Users\\atrij\\anaconda3\\envs\\tfdg\\lib\\site-packages\\tensorflow_estimator\\_api\\v1\\estimator\\__init__.py\", line 10, in <module>\n",
      "    from tensorflow_estimator._api.v1.estimator import experimental\n",
      "  File \"C:\\Users\\atrij\\anaconda3\\envs\\tfdg\\lib\\site-packages\\tensorflow_estimator\\_api\\v1\\estimator\\experimental\\__init__.py\", line 10, in <module>\n",
      "    from tensorflow_estimator.python.estimator.canned.dnn import dnn_logit_fn_builder\n",
      "  File \"C:\\Users\\atrij\\anaconda3\\envs\\tfdg\\lib\\site-packages\\tensorflow_estimator\\python\\estimator\\canned\\dnn.py\", line 27, in <module>\n",
      "    from tensorflow_estimator.python.estimator import estimator\n",
      "  File \"C:\\Users\\atrij\\anaconda3\\envs\\tfdg\\lib\\site-packages\\tensorflow_estimator\\python\\estimator\\estimator.py\", line 36, in <module>\n",
      "    from tensorflow.python.profiler import trace\n",
      "ImportError: cannot import name 'trace'\n",
      "Traceback (most recent call last):\n",
      "  File \"C:\\Users\\atrij\\anaconda3\\envs\\tfdg\\lib\\site-packages\\IPython\\core\\interactiveshell.py\", line 3343, in run_code\n",
      "    exec(code_obj, self.user_global_ns, self.user_ns)\n",
      "  File \"<ipython-input-4-8fd7a15cc125>\", line 1, in <module>\n",
      "    import cv2\n",
      "ModuleNotFoundError: No module named 'cv2'\n",
      "\n",
      "During handling of the above exception, another exception occurred:\n",
      "\n",
      "Traceback (most recent call last):\n",
      "  File \"C:\\Users\\atrij\\anaconda3\\envs\\tfdg\\lib\\site-packages\\IPython\\core\\interactiveshell.py\", line 2044, in showtraceback\n",
      "    stb = value._render_traceback_()\n",
      "AttributeError: 'ModuleNotFoundError' object has no attribute '_render_traceback_'\n",
      "\n",
      "During handling of the above exception, another exception occurred:\n",
      "\n",
      "Traceback (most recent call last):\n",
      "  File \"C:\\Users\\atrij\\anaconda3\\envs\\tfdg\\lib\\site-packages\\IPython\\core\\interactiveshell.py\", line 3263, in run_ast_nodes\n",
      "    if (await self.run_code(code, result,  async_=asy)):\n",
      "  File \"C:\\Users\\atrij\\anaconda3\\envs\\tfdg\\lib\\site-packages\\IPython\\core\\interactiveshell.py\", line 3360, in run_code\n",
      "    self.showtraceback(running_compiled_code=True)\n",
      "  File \"C:\\Users\\atrij\\anaconda3\\envs\\tfdg\\lib\\site-packages\\IPython\\core\\interactiveshell.py\", line 2047, in showtraceback\n",
      "    value, tb, tb_offset=tb_offset)\n",
      "  File \"C:\\Users\\atrij\\anaconda3\\envs\\tfdg\\lib\\site-packages\\IPython\\core\\ultratb.py\", line 1436, in structured_traceback\n",
      "    self, etype, value, tb, tb_offset, number_of_lines_of_context)\n",
      "  File \"C:\\Users\\atrij\\anaconda3\\envs\\tfdg\\lib\\site-packages\\IPython\\core\\ultratb.py\", line 1336, in structured_traceback\n",
      "    self, etype, value, tb, tb_offset, number_of_lines_of_context\n",
      "  File \"C:\\Users\\atrij\\anaconda3\\envs\\tfdg\\lib\\site-packages\\IPython\\core\\ultratb.py\", line 1193, in structured_traceback\n",
      "    tb_offset)\n",
      "  File \"C:\\Users\\atrij\\anaconda3\\envs\\tfdg\\lib\\site-packages\\IPython\\core\\ultratb.py\", line 1150, in format_exception_as_a_whole\n",
      "    last_unique, recursion_repeat = find_recursion(orig_etype, evalue, records)\n",
      "  File \"C:\\Users\\atrij\\anaconda3\\envs\\tfdg\\lib\\site-packages\\IPython\\core\\ultratb.py\", line 451, in find_recursion\n",
      "    return len(records), 0\n",
      "TypeError: object of type 'NoneType' has no len()\n",
      "\n",
      "During handling of the above exception, another exception occurred:\n",
      "\n",
      "Traceback (most recent call last):\n",
      "  File \"C:\\Users\\atrij\\anaconda3\\envs\\tfdg\\lib\\site-packages\\IPython\\core\\interactiveshell.py\", line 2044, in showtraceback\n",
      "    stb = value._render_traceback_()\n",
      "AttributeError: 'TypeError' object has no attribute '_render_traceback_'\n",
      "\n",
      "During handling of the above exception, another exception occurred:\n",
      "\n",
      "Traceback (most recent call last):\n",
      "  File \"C:\\Users\\atrij\\anaconda3\\envs\\tfdg\\lib\\site-packages\\IPython\\core\\ultratb.py\", line 1169, in get_records\n",
      "    return _fixed_getinnerframes(etb, number_of_lines_of_context, tb_offset)\n",
      "  File \"C:\\Users\\atrij\\anaconda3\\envs\\tfdg\\lib\\site-packages\\IPython\\core\\ultratb.py\", line 316, in wrapped\n",
      "    return f(*args, **kwargs)\n",
      "  File \"C:\\Users\\atrij\\anaconda3\\envs\\tfdg\\lib\\site-packages\\IPython\\core\\ultratb.py\", line 350, in _fixed_getinnerframes\n",
      "    records = fix_frame_records_filenames(inspect.getinnerframes(etb, context))\n",
      "  File \"C:\\Users\\atrij\\anaconda3\\envs\\tfdg\\lib\\inspect.py\", line 1490, in getinnerframes\n",
      "    frameinfo = (tb.tb_frame,) + getframeinfo(tb, context)\n",
      "  File \"C:\\Users\\atrij\\anaconda3\\envs\\tfdg\\lib\\inspect.py\", line 1448, in getframeinfo\n",
      "    filename = getsourcefile(frame) or getfile(frame)\n",
      "  File \"C:\\Users\\atrij\\anaconda3\\envs\\tfdg\\lib\\inspect.py\", line 696, in getsourcefile\n",
      "    if getattr(getmodule(object, filename), '__loader__', None) is not None:\n",
      "  File \"C:\\Users\\atrij\\anaconda3\\envs\\tfdg\\lib\\inspect.py\", line 733, in getmodule\n",
      "    if ismodule(module) and hasattr(module, '__file__'):\n",
      "  File \"C:\\Users\\atrij\\anaconda3\\envs\\tfdg\\lib\\site-packages\\tensorflow\\__init__.py\", line 50, in __getattr__\n",
      "    module = self._load()\n",
      "  File \"C:\\Users\\atrij\\anaconda3\\envs\\tfdg\\lib\\site-packages\\tensorflow\\__init__.py\", line 44, in _load\n",
      "    module = _importlib.import_module(self.__name__)\n",
      "  File \"C:\\Users\\atrij\\anaconda3\\envs\\tfdg\\lib\\importlib\\__init__.py\", line 126, in import_module\n",
      "    return _bootstrap._gcd_import(name[level:], package, level)\n",
      "  File \"<frozen importlib._bootstrap>\", line 994, in _gcd_import\n",
      "  File \"<frozen importlib._bootstrap>\", line 971, in _find_and_load\n",
      "  File \"<frozen importlib._bootstrap>\", line 953, in _find_and_load_unlocked\n",
      "ModuleNotFoundError: No module named 'tensorflow_core.estimator'\n",
      "Traceback (most recent call last):\n",
      "  File \"C:\\Users\\atrij\\anaconda3\\envs\\tfdg\\lib\\site-packages\\IPython\\core\\interactiveshell.py\", line 3343, in run_code\n",
      "    exec(code_obj, self.user_global_ns, self.user_ns)\n",
      "  File \"<ipython-input-4-8fd7a15cc125>\", line 1, in <module>\n",
      "    import cv2\n",
      "ModuleNotFoundError: No module named 'cv2'\n",
      "\n",
      "During handling of the above exception, another exception occurred:\n",
      "\n",
      "Traceback (most recent call last):\n",
      "  File \"C:\\Users\\atrij\\anaconda3\\envs\\tfdg\\lib\\site-packages\\IPython\\core\\interactiveshell.py\", line 2044, in showtraceback\n",
      "    stb = value._render_traceback_()\n",
      "AttributeError: 'ModuleNotFoundError' object has no attribute '_render_traceback_'\n",
      "\n",
      "During handling of the above exception, another exception occurred:\n",
      "\n",
      "Traceback (most recent call last):\n",
      "  File \"C:\\Users\\atrij\\anaconda3\\envs\\tfdg\\lib\\site-packages\\IPython\\core\\interactiveshell.py\", line 3263, in run_ast_nodes\n",
      "    if (await self.run_code(code, result,  async_=asy)):\n",
      "  File \"C:\\Users\\atrij\\anaconda3\\envs\\tfdg\\lib\\site-packages\\IPython\\core\\interactiveshell.py\", line 3360, in run_code\n",
      "    self.showtraceback(running_compiled_code=True)\n",
      "  File \"C:\\Users\\atrij\\anaconda3\\envs\\tfdg\\lib\\site-packages\\IPython\\core\\interactiveshell.py\", line 2047, in showtraceback\n",
      "    value, tb, tb_offset=tb_offset)\n",
      "  File \"C:\\Users\\atrij\\anaconda3\\envs\\tfdg\\lib\\site-packages\\IPython\\core\\ultratb.py\", line 1436, in structured_traceback\n",
      "    self, etype, value, tb, tb_offset, number_of_lines_of_context)\n",
      "  File \"C:\\Users\\atrij\\anaconda3\\envs\\tfdg\\lib\\site-packages\\IPython\\core\\ultratb.py\", line 1336, in structured_traceback\n",
      "    self, etype, value, tb, tb_offset, number_of_lines_of_context\n",
      "  File \"C:\\Users\\atrij\\anaconda3\\envs\\tfdg\\lib\\site-packages\\IPython\\core\\ultratb.py\", line 1193, in structured_traceback\n",
      "    tb_offset)\n",
      "  File \"C:\\Users\\atrij\\anaconda3\\envs\\tfdg\\lib\\site-packages\\IPython\\core\\ultratb.py\", line 1150, in format_exception_as_a_whole\n",
      "    last_unique, recursion_repeat = find_recursion(orig_etype, evalue, records)\n",
      "  File \"C:\\Users\\atrij\\anaconda3\\envs\\tfdg\\lib\\site-packages\\IPython\\core\\ultratb.py\", line 451, in find_recursion\n",
      "    return len(records), 0\n",
      "TypeError: object of type 'NoneType' has no len()\n",
      "\n",
      "During handling of the above exception, another exception occurred:\n",
      "\n",
      "Traceback (most recent call last):\n",
      "  File \"C:\\Users\\atrij\\anaconda3\\envs\\tfdg\\lib\\site-packages\\IPython\\core\\interactiveshell.py\", line 2044, in showtraceback\n",
      "    stb = value._render_traceback_()\n",
      "AttributeError: 'TypeError' object has no attribute '_render_traceback_'\n",
      "\n",
      "During handling of the above exception, another exception occurred:\n",
      "\n",
      "Traceback (most recent call last):\n",
      "  File \"C:\\Users\\atrij\\anaconda3\\envs\\tfdg\\lib\\site-packages\\IPython\\core\\interactiveshell.py\", line 2895, in _run_cell\n",
      "    return runner(coro)\n",
      "  File \"C:\\Users\\atrij\\anaconda3\\envs\\tfdg\\lib\\site-packages\\IPython\\core\\async_helpers.py\", line 68, in _pseudo_sync_runner\n",
      "    coro.send(None)\n",
      "  File \"C:\\Users\\atrij\\anaconda3\\envs\\tfdg\\lib\\site-packages\\IPython\\core\\interactiveshell.py\", line 3072, in run_cell_async\n",
      "    interactivity=interactivity, compiler=compiler, result=result)\n",
      "  File \"C:\\Users\\atrij\\anaconda3\\envs\\tfdg\\lib\\site-packages\\IPython\\core\\interactiveshell.py\", line 3282, in run_ast_nodes\n",
      "    self.showtraceback()\n",
      "  File \"C:\\Users\\atrij\\anaconda3\\envs\\tfdg\\lib\\site-packages\\IPython\\core\\interactiveshell.py\", line 2047, in showtraceback\n",
      "    value, tb, tb_offset=tb_offset)\n",
      "  File \"C:\\Users\\atrij\\anaconda3\\envs\\tfdg\\lib\\site-packages\\IPython\\core\\ultratb.py\", line 1436, in structured_traceback\n",
      "    self, etype, value, tb, tb_offset, number_of_lines_of_context)\n",
      "  File \"C:\\Users\\atrij\\anaconda3\\envs\\tfdg\\lib\\site-packages\\IPython\\core\\ultratb.py\", line 1336, in structured_traceback\n",
      "    self, etype, value, tb, tb_offset, number_of_lines_of_context\n",
      "  File \"C:\\Users\\atrij\\anaconda3\\envs\\tfdg\\lib\\site-packages\\IPython\\core\\ultratb.py\", line 1211, in structured_traceback\n",
      "    chained_exceptions_tb_offset)\n",
      "  File \"C:\\Users\\atrij\\anaconda3\\envs\\tfdg\\lib\\site-packages\\IPython\\core\\ultratb.py\", line 1150, in format_exception_as_a_whole\n",
      "    last_unique, recursion_repeat = find_recursion(orig_etype, evalue, records)\n",
      "  File \"C:\\Users\\atrij\\anaconda3\\envs\\tfdg\\lib\\site-packages\\IPython\\core\\ultratb.py\", line 451, in find_recursion\n",
      "    return len(records), 0\n",
      "TypeError: object of type 'NoneType' has no len()\n",
      "\n",
      "During handling of the above exception, another exception occurred:\n",
      "\n",
      "Traceback (most recent call last):\n",
      "  File \"C:\\Users\\atrij\\anaconda3\\envs\\tfdg\\lib\\site-packages\\IPython\\core\\interactiveshell.py\", line 2044, in showtraceback\n",
      "    stb = value._render_traceback_()\n",
      "AttributeError: 'TypeError' object has no attribute '_render_traceback_'\n",
      "\n",
      "During handling of the above exception, another exception occurred:\n",
      "\n",
      "Traceback (most recent call last):\n",
      "  File \"C:\\Users\\atrij\\anaconda3\\envs\\tfdg\\lib\\site-packages\\IPython\\core\\ultratb.py\", line 1169, in get_records\n",
      "    return _fixed_getinnerframes(etb, number_of_lines_of_context, tb_offset)\n",
      "  File \"C:\\Users\\atrij\\anaconda3\\envs\\tfdg\\lib\\site-packages\\IPython\\core\\ultratb.py\", line 316, in wrapped\n",
      "    return f(*args, **kwargs)\n",
      "  File \"C:\\Users\\atrij\\anaconda3\\envs\\tfdg\\lib\\site-packages\\IPython\\core\\ultratb.py\", line 350, in _fixed_getinnerframes\n",
      "    records = fix_frame_records_filenames(inspect.getinnerframes(etb, context))\n",
      "  File \"C:\\Users\\atrij\\anaconda3\\envs\\tfdg\\lib\\inspect.py\", line 1490, in getinnerframes\n",
      "    frameinfo = (tb.tb_frame,) + getframeinfo(tb, context)\n",
      "  File \"C:\\Users\\atrij\\anaconda3\\envs\\tfdg\\lib\\inspect.py\", line 1448, in getframeinfo\n",
      "    filename = getsourcefile(frame) or getfile(frame)\n",
      "  File \"C:\\Users\\atrij\\anaconda3\\envs\\tfdg\\lib\\inspect.py\", line 696, in getsourcefile\n",
      "    if getattr(getmodule(object, filename), '__loader__', None) is not None:\n",
      "  File \"C:\\Users\\atrij\\anaconda3\\envs\\tfdg\\lib\\inspect.py\", line 733, in getmodule\n",
      "    if ismodule(module) and hasattr(module, '__file__'):\n",
      "  File \"C:\\Users\\atrij\\anaconda3\\envs\\tfdg\\lib\\site-packages\\tensorflow\\__init__.py\", line 50, in __getattr__\n",
      "    module = self._load()\n",
      "  File \"C:\\Users\\atrij\\anaconda3\\envs\\tfdg\\lib\\site-packages\\tensorflow\\__init__.py\", line 44, in _load\n",
      "    module = _importlib.import_module(self.__name__)\n",
      "  File \"C:\\Users\\atrij\\anaconda3\\envs\\tfdg\\lib\\importlib\\__init__.py\", line 126, in import_module\n",
      "    return _bootstrap._gcd_import(name[level:], package, level)\n",
      "  File \"<frozen importlib._bootstrap>\", line 994, in _gcd_import\n",
      "  File \"<frozen importlib._bootstrap>\", line 971, in _find_and_load\n",
      "  File \"<frozen importlib._bootstrap>\", line 953, in _find_and_load_unlocked\n",
      "ModuleNotFoundError: No module named 'tensorflow_core.estimator'\n"
     ]
    }
   ],
   "source": [
    "import cv2\n",
    "import os"
   ]
  },
  {
   "cell_type": "code",
   "execution_count": null,
   "id": "38dda2c6",
   "metadata": {},
   "outputs": [
    {
     "name": "stderr",
     "output_type": "stream",
     "text": [
      "ERROR:root:Internal Python error in the inspect module.\n",
      "Below is the traceback from this internal error.\n",
      "\n",
      "ERROR:root:Internal Python error in the inspect module.\n",
      "Below is the traceback from this internal error.\n",
      "\n",
      "ERROR:root:Internal Python error in the inspect module.\n",
      "Below is the traceback from this internal error.\n",
      "\n"
     ]
    },
    {
     "name": "stdout",
     "output_type": "stream",
     "text": [
      "Traceback (most recent call last):\n",
      "  File \"C:\\Users\\atrij\\anaconda3\\envs\\tfdg\\lib\\site-packages\\IPython\\core\\interactiveshell.py\", line 3343, in run_code\n",
      "    exec(code_obj, self.user_global_ns, self.user_ns)\n",
      "  File \"<ipython-input-4-6b472a301922>\", line 2, in <module>\n",
      "    categories = os.listdir(data_path)\n",
      "NameError: name 'os' is not defined\n",
      "\n",
      "During handling of the above exception, another exception occurred:\n",
      "\n",
      "Traceback (most recent call last):\n",
      "  File \"C:\\Users\\atrij\\anaconda3\\envs\\tfdg\\lib\\site-packages\\IPython\\core\\interactiveshell.py\", line 2044, in showtraceback\n",
      "    stb = value._render_traceback_()\n",
      "AttributeError: 'NameError' object has no attribute '_render_traceback_'\n",
      "\n",
      "During handling of the above exception, another exception occurred:\n",
      "\n",
      "Traceback (most recent call last):\n",
      "  File \"C:\\Users\\atrij\\anaconda3\\envs\\tfdg\\lib\\site-packages\\IPython\\core\\ultratb.py\", line 1169, in get_records\n",
      "    return _fixed_getinnerframes(etb, number_of_lines_of_context, tb_offset)\n",
      "  File \"C:\\Users\\atrij\\anaconda3\\envs\\tfdg\\lib\\site-packages\\IPython\\core\\ultratb.py\", line 316, in wrapped\n",
      "    return f(*args, **kwargs)\n",
      "  File \"C:\\Users\\atrij\\anaconda3\\envs\\tfdg\\lib\\site-packages\\IPython\\core\\ultratb.py\", line 350, in _fixed_getinnerframes\n",
      "    records = fix_frame_records_filenames(inspect.getinnerframes(etb, context))\n",
      "  File \"C:\\Users\\atrij\\anaconda3\\envs\\tfdg\\lib\\inspect.py\", line 1490, in getinnerframes\n",
      "    frameinfo = (tb.tb_frame,) + getframeinfo(tb, context)\n",
      "  File \"C:\\Users\\atrij\\anaconda3\\envs\\tfdg\\lib\\inspect.py\", line 1448, in getframeinfo\n",
      "    filename = getsourcefile(frame) or getfile(frame)\n",
      "  File \"C:\\Users\\atrij\\anaconda3\\envs\\tfdg\\lib\\inspect.py\", line 696, in getsourcefile\n",
      "    if getattr(getmodule(object, filename), '__loader__', None) is not None:\n",
      "  File \"C:\\Users\\atrij\\anaconda3\\envs\\tfdg\\lib\\inspect.py\", line 733, in getmodule\n",
      "    if ismodule(module) and hasattr(module, '__file__'):\n",
      "  File \"C:\\Users\\atrij\\anaconda3\\envs\\tfdg\\lib\\site-packages\\tensorflow\\__init__.py\", line 50, in __getattr__\n",
      "    module = self._load()\n",
      "  File \"C:\\Users\\atrij\\anaconda3\\envs\\tfdg\\lib\\site-packages\\tensorflow\\__init__.py\", line 44, in _load\n",
      "    module = _importlib.import_module(self.__name__)\n",
      "ERROR! Session/line number was not unique in database. History logging moved to new session  File \"C:\\Users\\atrij\\anaconda3\\envs\\tfdg\\lib\\importlib\\__init__.py\", line 126, in import_module\n",
      "    return _bootstrap._gcd_import(name[level:], package, level)\n",
      "  File \"<frozen importlib._bootstrap>\", line 994, in _gcd_import\n",
      "  File \"<frozen importlib._bootstrap>\", line 971, in _find_and_load\n",
      "   File \"<frozen importlib._bootstrap>\", line 953, in _find_and_load_unlocked\n",
      "ModuleNotFoundError: No module named 'tensorflow_core.estimator'\n",
      "50\n",
      "Traceback (most recent call last):\n",
      "  File \"C:\\Users\\atrij\\anaconda3\\envs\\tfdg\\lib\\site-packages\\IPython\\core\\interactiveshell.py\", line 3343, in run_code\n",
      "    exec(code_obj, self.user_global_ns, self.user_ns)\n",
      "  File \"<ipython-input-4-6b472a301922>\", line 2, in <module>\n",
      "    categories = os.listdir(data_path)\n",
      "NameError: name 'os' is not defined\n",
      "\n",
      "During handling of the above exception, another exception occurred:\n",
      "\n",
      "Traceback (most recent call last):\n",
      "  File \"C:\\Users\\atrij\\anaconda3\\envs\\tfdg\\lib\\site-packages\\IPython\\core\\interactiveshell.py\", line 2044, in showtraceback\n",
      "    stb = value._render_traceback_()\n",
      "AttributeError: 'NameError' object has no attribute '_render_traceback_'\n",
      "\n",
      "During handling of the above exception, another exception occurred:\n",
      "\n",
      "Traceback (most recent call last):\n",
      "  File \"C:\\Users\\atrij\\anaconda3\\envs\\tfdg\\lib\\site-packages\\IPython\\core\\interactiveshell.py\", line 3263, in run_ast_nodes\n",
      "    if (await self.run_code(code, result,  async_=asy)):\n",
      "  File \"C:\\Users\\atrij\\anaconda3\\envs\\tfdg\\lib\\site-packages\\IPython\\core\\interactiveshell.py\", line 3360, in run_code\n",
      "    self.showtraceback(running_compiled_code=True)\n",
      "  File \"C:\\Users\\atrij\\anaconda3\\envs\\tfdg\\lib\\site-packages\\IPython\\core\\interactiveshell.py\", line 2047, in showtraceback\n",
      "    value, tb, tb_offset=tb_offset)\n",
      "  File \"C:\\Users\\atrij\\anaconda3\\envs\\tfdg\\lib\\site-packages\\IPython\\core\\ultratb.py\", line 1436, in structured_traceback\n",
      "    self, etype, value, tb, tb_offset, number_of_lines_of_context)\n",
      "  File \"C:\\Users\\atrij\\anaconda3\\envs\\tfdg\\lib\\site-packages\\IPython\\core\\ultratb.py\", line 1336, in structured_traceback\n",
      "    self, etype, value, tb, tb_offset, number_of_lines_of_context\n",
      "  File \"C:\\Users\\atrij\\anaconda3\\envs\\tfdg\\lib\\site-packages\\IPython\\core\\ultratb.py\", line 1193, in structured_traceback\n",
      "    tb_offset)\n",
      "  File \"C:\\Users\\atrij\\anaconda3\\envs\\tfdg\\lib\\site-packages\\IPython\\core\\ultratb.py\", line 1150, in format_exception_as_a_whole\n",
      "    last_unique, recursion_repeat = find_recursion(orig_etype, evalue, records)\n",
      "  File \"C:\\Users\\atrij\\anaconda3\\envs\\tfdg\\lib\\site-packages\\IPython\\core\\ultratb.py\", line 451, in find_recursion\n",
      "    return len(records), 0\n",
      "TypeError: object of type 'NoneType' has no len()\n",
      "\n",
      "During handling of the above exception, another exception occurred:\n",
      "\n",
      "Traceback (most recent call last):\n",
      "  File \"C:\\Users\\atrij\\anaconda3\\envs\\tfdg\\lib\\site-packages\\IPython\\core\\interactiveshell.py\", line 2044, in showtraceback\n",
      "    stb = value._render_traceback_()\n",
      "AttributeError: 'TypeError' object has no attribute '_render_traceback_'\n",
      "\n",
      "During handling of the above exception, another exception occurred:\n",
      "\n",
      "Traceback (most recent call last):\n",
      "  File \"C:\\Users\\atrij\\anaconda3\\envs\\tfdg\\lib\\site-packages\\IPython\\core\\ultratb.py\", line 1169, in get_records\n",
      "    return _fixed_getinnerframes(etb, number_of_lines_of_context, tb_offset)\n",
      "  File \"C:\\Users\\atrij\\anaconda3\\envs\\tfdg\\lib\\site-packages\\IPython\\core\\ultratb.py\", line 316, in wrapped\n",
      "    return f(*args, **kwargs)\n",
      "  File \"C:\\Users\\atrij\\anaconda3\\envs\\tfdg\\lib\\site-packages\\IPython\\core\\ultratb.py\", line 350, in _fixed_getinnerframes\n",
      "    records = fix_frame_records_filenames(inspect.getinnerframes(etb, context))\n",
      "  File \"C:\\Users\\atrij\\anaconda3\\envs\\tfdg\\lib\\inspect.py\", line 1490, in getinnerframes\n",
      "    frameinfo = (tb.tb_frame,) + getframeinfo(tb, context)\n",
      "  File \"C:\\Users\\atrij\\anaconda3\\envs\\tfdg\\lib\\inspect.py\", line 1448, in getframeinfo\n",
      "    filename = getsourcefile(frame) or getfile(frame)\n",
      "  File \"C:\\Users\\atrij\\anaconda3\\envs\\tfdg\\lib\\inspect.py\", line 696, in getsourcefile\n",
      "    if getattr(getmodule(object, filename), '__loader__', None) is not None:\n",
      "  File \"C:\\Users\\atrij\\anaconda3\\envs\\tfdg\\lib\\inspect.py\", line 733, in getmodule\n",
      "    if ismodule(module) and hasattr(module, '__file__'):\n",
      "  File \"C:\\Users\\atrij\\anaconda3\\envs\\tfdg\\lib\\site-packages\\tensorflow\\__init__.py\", line 50, in __getattr__\n",
      "    module = self._load()\n",
      "  File \"C:\\Users\\atrij\\anaconda3\\envs\\tfdg\\lib\\site-packages\\tensorflow\\__init__.py\", line 44, in _load\n",
      "    module = _importlib.import_module(self.__name__)\n",
      "  File \"C:\\Users\\atrij\\anaconda3\\envs\\tfdg\\lib\\importlib\\__init__.py\", line 126, in import_module\n",
      "    return _bootstrap._gcd_import(name[level:], package, level)\n",
      "  File \"<frozen importlib._bootstrap>\", line 994, in _gcd_import\n",
      "  File \"<frozen importlib._bootstrap>\", line 971, in _find_and_load\n",
      "  File \"<frozen importlib._bootstrap>\", line 953, in _find_and_load_unlocked\n",
      "ModuleNotFoundError: No module named 'tensorflow_core.estimator'\n",
      "Traceback (most recent call last):\n",
      "  File \"C:\\Users\\atrij\\anaconda3\\envs\\tfdg\\lib\\site-packages\\IPython\\core\\interactiveshell.py\", line 3343, in run_code\n",
      "    exec(code_obj, self.user_global_ns, self.user_ns)\n",
      "  File \"<ipython-input-4-6b472a301922>\", line 2, in <module>\n",
      "    categories = os.listdir(data_path)\n",
      "NameError: name 'os' is not defined\n",
      "\n",
      "During handling of the above exception, another exception occurred:\n",
      "\n",
      "Traceback (most recent call last):\n",
      "  File \"C:\\Users\\atrij\\anaconda3\\envs\\tfdg\\lib\\site-packages\\IPython\\core\\interactiveshell.py\", line 2044, in showtraceback\n",
      "    stb = value._render_traceback_()\n",
      "AttributeError: 'NameError' object has no attribute '_render_traceback_'\n",
      "\n",
      "During handling of the above exception, another exception occurred:\n",
      "\n",
      "Traceback (most recent call last):\n",
      "  File \"C:\\Users\\atrij\\anaconda3\\envs\\tfdg\\lib\\site-packages\\IPython\\core\\interactiveshell.py\", line 3263, in run_ast_nodes\n",
      "    if (await self.run_code(code, result,  async_=asy)):\n",
      "  File \"C:\\Users\\atrij\\anaconda3\\envs\\tfdg\\lib\\site-packages\\IPython\\core\\interactiveshell.py\", line 3360, in run_code\n",
      "    self.showtraceback(running_compiled_code=True)\n",
      "  File \"C:\\Users\\atrij\\anaconda3\\envs\\tfdg\\lib\\site-packages\\IPython\\core\\interactiveshell.py\", line 2047, in showtraceback\n",
      "    value, tb, tb_offset=tb_offset)\n",
      "  File \"C:\\Users\\atrij\\anaconda3\\envs\\tfdg\\lib\\site-packages\\IPython\\core\\ultratb.py\", line 1436, in structured_traceback\n",
      "    self, etype, value, tb, tb_offset, number_of_lines_of_context)\n",
      "  File \"C:\\Users\\atrij\\anaconda3\\envs\\tfdg\\lib\\site-packages\\IPython\\core\\ultratb.py\", line 1336, in structured_traceback\n",
      "    self, etype, value, tb, tb_offset, number_of_lines_of_context\n",
      "  File \"C:\\Users\\atrij\\anaconda3\\envs\\tfdg\\lib\\site-packages\\IPython\\core\\ultratb.py\", line 1193, in structured_traceback\n",
      "    tb_offset)\n",
      "  File \"C:\\Users\\atrij\\anaconda3\\envs\\tfdg\\lib\\site-packages\\IPython\\core\\ultratb.py\", line 1150, in format_exception_as_a_whole\n",
      "    last_unique, recursion_repeat = find_recursion(orig_etype, evalue, records)\n",
      "  File \"C:\\Users\\atrij\\anaconda3\\envs\\tfdg\\lib\\site-packages\\IPython\\core\\ultratb.py\", line 451, in find_recursion\n",
      "    return len(records), 0\n",
      "TypeError: object of type 'NoneType' has no len()\n",
      "\n",
      "During handling of the above exception, another exception occurred:\n",
      "\n",
      "Traceback (most recent call last):\n",
      "  File \"C:\\Users\\atrij\\anaconda3\\envs\\tfdg\\lib\\site-packages\\IPython\\core\\interactiveshell.py\", line 2044, in showtraceback\n",
      "    stb = value._render_traceback_()\n",
      "AttributeError: 'TypeError' object has no attribute '_render_traceback_'\n",
      "\n",
      "During handling of the above exception, another exception occurred:\n",
      "\n",
      "Traceback (most recent call last):\n",
      "  File \"C:\\Users\\atrij\\anaconda3\\envs\\tfdg\\lib\\site-packages\\IPython\\core\\interactiveshell.py\", line 2895, in _run_cell\n",
      "    return runner(coro)\n",
      "  File \"C:\\Users\\atrij\\anaconda3\\envs\\tfdg\\lib\\site-packages\\IPython\\core\\async_helpers.py\", line 68, in _pseudo_sync_runner\n",
      "    coro.send(None)\n",
      "  File \"C:\\Users\\atrij\\anaconda3\\envs\\tfdg\\lib\\site-packages\\IPython\\core\\interactiveshell.py\", line 3072, in run_cell_async\n",
      "    interactivity=interactivity, compiler=compiler, result=result)\n",
      "  File \"C:\\Users\\atrij\\anaconda3\\envs\\tfdg\\lib\\site-packages\\IPython\\core\\interactiveshell.py\", line 3282, in run_ast_nodes\n",
      "    self.showtraceback()\n",
      "  File \"C:\\Users\\atrij\\anaconda3\\envs\\tfdg\\lib\\site-packages\\IPython\\core\\interactiveshell.py\", line 2047, in showtraceback\n",
      "    value, tb, tb_offset=tb_offset)\n",
      "  File \"C:\\Users\\atrij\\anaconda3\\envs\\tfdg\\lib\\site-packages\\IPython\\core\\ultratb.py\", line 1436, in structured_traceback\n",
      "    self, etype, value, tb, tb_offset, number_of_lines_of_context)\n",
      "  File \"C:\\Users\\atrij\\anaconda3\\envs\\tfdg\\lib\\site-packages\\IPython\\core\\ultratb.py\", line 1336, in structured_traceback\n",
      "    self, etype, value, tb, tb_offset, number_of_lines_of_context\n",
      "  File \"C:\\Users\\atrij\\anaconda3\\envs\\tfdg\\lib\\site-packages\\IPython\\core\\ultratb.py\", line 1211, in structured_traceback\n",
      "    chained_exceptions_tb_offset)\n",
      "  File \"C:\\Users\\atrij\\anaconda3\\envs\\tfdg\\lib\\site-packages\\IPython\\core\\ultratb.py\", line 1150, in format_exception_as_a_whole\n",
      "    last_unique, recursion_repeat = find_recursion(orig_etype, evalue, records)\n",
      "  File \"C:\\Users\\atrij\\anaconda3\\envs\\tfdg\\lib\\site-packages\\IPython\\core\\ultratb.py\", line 451, in find_recursion\n",
      "    return len(records), 0\n",
      "TypeError: object of type 'NoneType' has no len()\n",
      "\n",
      "During handling of the above exception, another exception occurred:\n",
      "\n",
      "Traceback (most recent call last):\n",
      "  File \"C:\\Users\\atrij\\anaconda3\\envs\\tfdg\\lib\\site-packages\\IPython\\core\\interactiveshell.py\", line 2044, in showtraceback\n",
      "    stb = value._render_traceback_()\n",
      "AttributeError: 'TypeError' object has no attribute '_render_traceback_'\n",
      "\n",
      "During handling of the above exception, another exception occurred:\n",
      "\n",
      "Traceback (most recent call last):\n",
      "  File \"C:\\Users\\atrij\\anaconda3\\envs\\tfdg\\lib\\site-packages\\IPython\\core\\ultratb.py\", line 1169, in get_records\n",
      "    return _fixed_getinnerframes(etb, number_of_lines_of_context, tb_offset)\n",
      "  File \"C:\\Users\\atrij\\anaconda3\\envs\\tfdg\\lib\\site-packages\\IPython\\core\\ultratb.py\", line 316, in wrapped\n",
      "    return f(*args, **kwargs)\n",
      "  File \"C:\\Users\\atrij\\anaconda3\\envs\\tfdg\\lib\\site-packages\\IPython\\core\\ultratb.py\", line 350, in _fixed_getinnerframes\n",
      "    records = fix_frame_records_filenames(inspect.getinnerframes(etb, context))\n",
      "  File \"C:\\Users\\atrij\\anaconda3\\envs\\tfdg\\lib\\inspect.py\", line 1490, in getinnerframes\n",
      "    frameinfo = (tb.tb_frame,) + getframeinfo(tb, context)\n",
      "  File \"C:\\Users\\atrij\\anaconda3\\envs\\tfdg\\lib\\inspect.py\", line 1448, in getframeinfo\n",
      "    filename = getsourcefile(frame) or getfile(frame)\n",
      "  File \"C:\\Users\\atrij\\anaconda3\\envs\\tfdg\\lib\\inspect.py\", line 696, in getsourcefile\n",
      "    if getattr(getmodule(object, filename), '__loader__', None) is not None:\n",
      "  File \"C:\\Users\\atrij\\anaconda3\\envs\\tfdg\\lib\\inspect.py\", line 733, in getmodule\n",
      "    if ismodule(module) and hasattr(module, '__file__'):\n",
      "  File \"C:\\Users\\atrij\\anaconda3\\envs\\tfdg\\lib\\site-packages\\tensorflow\\__init__.py\", line 50, in __getattr__\n",
      "    module = self._load()\n",
      "  File \"C:\\Users\\atrij\\anaconda3\\envs\\tfdg\\lib\\site-packages\\tensorflow\\__init__.py\", line 44, in _load\n",
      "    module = _importlib.import_module(self.__name__)\n",
      "  File \"C:\\Users\\atrij\\anaconda3\\envs\\tfdg\\lib\\importlib\\__init__.py\", line 126, in import_module\n",
      "    return _bootstrap._gcd_import(name[level:], package, level)\n",
      "  File \"<frozen importlib._bootstrap>\", line 994, in _gcd_import\n",
      "  File \"<frozen importlib._bootstrap>\", line 971, in _find_and_load\n",
      "  File \"<frozen importlib._bootstrap>\", line 953, in _find_and_load_unlocked\n",
      "ModuleNotFoundError: No module named 'tensorflow_core.estimator'\n"
     ]
    }
   ],
   "source": [
    "data_path = \"C:\\\\Users\\\\atrij\\\\OneDrive\\\\Desktop\\\\DeepLearning\\\\Arthritis\\\\Digital Knee X-ray Images\\\\Digital Knee X-ray Images\\\\Knee X-ray Images\\\\MedicalExpert-I\"\n",
    "categories = os.listdir(data_path)\n",
    "labels = [i for i in range(len(categories))]\n",
    "\n",
    "label_dict = dict(zip(categories , labels))\n",
    "print(label_dict)\n",
    "print(categories)\n",
    "print(labels)"
   ]
  },
  {
   "cell_type": "code",
   "execution_count": null,
   "id": "a764a495",
   "metadata": {},
   "outputs": [],
   "source": []
  }
 ],
 "metadata": {
  "kernelspec": {
   "display_name": "Python 3",
   "language": "python",
   "name": "python3"
  },
  "language_info": {
   "codemirror_mode": {
    "name": "ipython",
    "version": 3
   },
   "file_extension": ".py",
   "mimetype": "text/x-python",
   "name": "python",
   "nbconvert_exporter": "python",
   "pygments_lexer": "ipython3",
   "version": "3.6.13"
  }
 },
 "nbformat": 4,
 "nbformat_minor": 5
}
